whats this error about. 

help solve it accurately

24/04/17 15:56:28 WARN TaskSetManager: Lost task 0.0 in stage 10398.0 (TID 9621) (10.4.7.192 executor 1): org.apache.spark.api.python.PythonException: Traceback (most recent call last):
  File "/tmp/ipykernel_324/537754424.py", line 23, in perform_regression
  File "/usr/local/lib/python3.10/dist-packages/scipy/stats/_stats_mstats_common.py", line 156, in linregress
    if np.amax(x) == np.amin(x) and len(x) > 1:
  File "/usr/local/lib/python3.10/dist-packages/numpy/core/fromnumeric.py", line 2827, in amax
    return _wrapreduction(a, np.maximum, 'max', axis, None, out,
  File "/usr/local/lib/python3.10/dist-packages/numpy/core/fromnumeric.py", line 88, in _wrapreduction
    return ufunc.reduce(obj, axis, dtype, out, **passkwargs)
numpy.core._exceptions._UFuncNoLoopError: ufunc 'maximum' did not contain a loop with signature matching types (dtype('<U4'), dtype('<U4')) -> None

	at org.apache.spark.api.python.BasePythonRunner$ReaderIterator.handlePythonException(PythonRunner.scala:572)
	at org.apache.spark.sql.execution.python.BasePythonUDFRunner$$anon$1.read(PythonUDFRunner.scala:94)
	at org.apache.spark.sql.execution.python.BasePythonUDFRunner$$anon$1.read(PythonUDFRunner.scala:75)
	at org.apache.spark.api.python.BasePythonRunner$ReaderIterator.hasNext(PythonRunner.scala:525)
	at org.apache.spark.InterruptibleIterator.hasNext(InterruptibleIterator.scala:37)
	at scala.collection.Iterator$$anon$11.hasNext(Iterator.scala:491)
	at scala.collection.Iterator$$anon$10.hasNext(Iterator.scala:460)
	at scala.collection.Iterator$$anon$10.hasNext(Iterator.scala:460)
	at org.apache.spark.sql.catalyst.expressions.GeneratedClass$GeneratedIteratorForCodegenStage103.processNext(Unknown Source)
	at org.apache.spark.sql.execution.BufferedRowIterator.hasNext(BufferedRowIterator.java:43)
	at org.apache.spark.sql.execution.WholeStageCodegenEvaluatorFactory$WholeStageCodegenPartitionEvaluator$$anon$1.hasNext(WholeStageCodegenEvaluatorFactory.scala:43)
	at org.apache.spark.sql.execution.SparkPlan.$anonfun$getByteArrayRdd$1(SparkPlan.scala:388)
	at org.apache.spark.rdd.RDD.$anonfun$mapPartitionsInternal$2(RDD.scala:890)
	at org.apache.spark.rdd.RDD.$anonfun$mapPartitionsInternal$2$adapted(RDD.scala:890)
	at org.apache.spark.rdd.MapPartitionsRDD.compute(MapPartitionsRDD.scala:52)
	at org.apache.spark.rdd.RDD.computeOrReadCheckpoint(RDD.scala:364)
	at org.apache.spark.rdd.RDD.iterator(RDD.scala:328)
	at org.apache.spark.scheduler.ResultTask.runTask(ResultTask.scala:93)
	at org.apache.spark.TaskContext.runTaskWithListeners(TaskContext.scala:161)
	at org.apache.spark.scheduler.Task.run(Task.scala:141)
	at org.apache.spark.executor.Executor$TaskRunner.$anonfun$run$4(Executor.scala:620)
	at org.apache.spark.util.SparkErrorUtils.tryWithSafeFinally(SparkErrorUtils.scala:64)
	at org.apache.spark.util.SparkErrorUtils.tryWithSafeFinally$(SparkErrorUtils.scala:61)
	at org.apache.spark.util.Utils$.tryWithSafeFinally(Utils.scala:94)
	at org.apache.spark.executor.Executor$TaskRunner.run(Executor.scala:623)
	at java.base/java.util.concurrent.ThreadPoolExecutor.runWorker(ThreadPoolExecutor.java:1136)
	at java.base/java.util.concurrent.ThreadPoolExecutor$Worker.run(ThreadPoolExecutor.java:635)
	at java.base/java.lang.Thread.run(Thread.java:840)

24/04/17 15:56:29 ERROR TaskSetManager: Task 0 in stage 10398.0 failed 4 times; aborting job
---------------------------------------------------------------------------
PythonException                           Traceback (most recent call last)
/tmp/ipykernel_324/537754424.py in <cell line: 57>()
     55 
     56 # Show final results
---> 57 results.show()
     58 
     59 # Assuming you might also want to save or further process the results

/usr/local/lib/python3.10/dist-packages/pyspark/sql/dataframe.py in show(self, n, truncate, vertical)
    957 
    958         if isinstance(truncate, bool) and truncate:
--> 959             print(self._jdf.showString(n, 20, vertical))
    960         else:
    961             try:

/usr/local/lib/python3.10/dist-packages/py4j/java_gateway.py in __call__(self, *args)
   1320 
   1321         answer = self.gateway_client.send_command(command)
-> 1322         return_value = get_return_value(
   1323             answer, self.gateway_client, self.target_id, self.name)
   1324 

/usr/local/lib/python3.10/dist-packages/pyspark/errors/exceptions/captured.py in deco(*a, **kw)
    183                 # Hide where the exception came from that shows a non-Pythonic
    184                 # JVM exception message.
--> 185                 raise converted from None
    186             else:
    187                 raise

PythonException: 
  An exception was thrown from the Python worker. Please see the stack trace below.
Traceback (most recent call last):
  File "/tmp/ipykernel_324/537754424.py", line 23, in perform_regression
  File "/usr/local/lib/python3.10/dist-packages/scipy/stats/_stats_mstats_common.py", line 156, in linregress
    if np.amax(x) == np.amin(x) and len(x) > 1:
  File "/usr/local/lib/python3.10/dist-packages/numpy/core/fromnumeric.py", line 2827, in amax
    return _wrapreduction(a, np.maximum, 'max', axis, None, out,
  File "/usr/local/lib/python3.10/dist-packages/numpy/core/fromnumeric.py", line 88, in _wrapreduction
    return ufunc.reduce(obj, axis, dtype, out, **passkwargs)
numpy.core._exceptions._UFuncNoLoopError: ufunc 'maximum' did not contain a loop with signature matching types (dtype('<U4'), dtype('<U4')) -> None
